<?xml version="1.0"?>
<robot name="pathfinder_simple" xmlns:xacro="http://ros.org/wiki/xacro">
    <gazebo>
        <plugin name="gazebo_ros_control" filename="libgazebo_ros_control.so">
            <robotNamespace>/pathfinder</robotNamespace>
        </plugin>
        <plugin name="p3d_base_controller" filename="libgazebo_ros_p3d.so">
            <alwaysOn>true</alwaysOn>
            <updateRate>50.0</updateRate>
            <bodyName>base_link</bodyName>
            <topicName>odom</topicName>
            <gaussianNoise>0.01</gaussianNoise>
            <frameName>world</frameName>
            <xyzOffsets>0 0 0</xyzOffsets>
            <rpyOffsets>0 0 0</rpyOffsets>
        </plugin>
    </gazebo>
    <link name="base_link">
        <visual>
            <geometry>
                <box size= "0.40 0.15 0.15"/>
            </geometry>
            <origin xyz="0 0 0" rpy="0 0 0"/>
        </visual>
        <inertial>
            <mass value="10"/>
            <inertia ixx="0.2" ixy="0.0" ixz="0.0" iyy="0.4" iyz="0.0" izz="0.2"/>
            <origin xyz="0 0 0" rpy="0 0 0"/>
        </inertial>
        <collision>
            <geometry>
                <box size="0.15 0.40 0.15"/>
            </geometry>
            <origin xyz="0 0 0" rpy="0 0 0"/>
        </collision>
    </link>
    <link name="front_left_wheel">
        <visual>
            <geometry>
                <cylinder length="0.1" radius="0.1"/>
            </geometry>
            <origin xyz="0 0 0" rpy="1.571 0 0"/>
        </visual>
        <inertial>
            <mass value="2"/>
            <inertia ixx="0.6" ixy="0.0" ixz="0.0" iyy="0.2" iyz="0.0" izz="0.2"/>
            <origin xyz="0 0 0" rpy="1.571 0 0"/>
        </inertial>
        <collision>
            <geometry>
                <cylinder length="0.1" radius="0.1"/>
            </geometry>
            <origin xyz="0 0 0" rpy="1.571 0 0"/>
        </collision>
    </link>
    <joint name="base_to_front_left" type="continuous">
        <parent link="base_link"/>
        <child link="front_left_wheel"/>
        <origin xyz="0.2 0.2 -0.1"/>
        <axis xyz="0 1 0"/>
    </joint>
    <link name="front_right_wheel">
        <visual>
            <geometry>
                <cylinder length="0.1" radius="0.1"/>
            </geometry>
            <origin xyz="0 0 0" rpy="1.571 0 0"/>
        </visual>
        <inertial>
            <mass value="2"/>
            <inertia ixx="0.6" ixy="0.0" ixz="0.0" iyy="0.2" iyz="0.0" izz="0.2"/>
            <origin xyz="0 0 0" rpy="1.571 0 0"/>
        </inertial>
        <collision>
            <geometry>
                <cylinder length="0.1" radius="0.1"/>
            </geometry>
            <origin xyz="0 0 0" rpy="1.571 0 0"/>
        </collision>
    </link>
    <joint name="base_to_front_right" type="continuous">
        <parent link="base_link"/>
        <child link="front_right_wheel"/>
        <origin xyz="0.2 -0.2 -0.1"/>
        <axis xyz="0 1 0"/>
    </joint>
    <link name="back_left_wheel">
        <visual>
            <geometry>
                <cylinder length="0.1" radius="0.1"/>
            </geometry>
            <origin xyz="0 0 0" rpy="1.571 0 0"/>
        </visual>
        <inertial>
            <mass value="2"/>
            <inertia ixx="0.6" ixy="0.0" ixz="0.0" iyy="0.2" iyz="0.0" izz="0.2"/>
            <origin xyz="0 0 0" rpy="1.571 0 0"/>
        </inertial>
        <collision>
            <geometry>
                <cylinder length="0.1" radius="0.1"/>
            </geometry>
            <origin xyz="0 0 0" rpy="1.571 0 0"/>
        </collision>
    </link>
    <joint name="base_to_back_left" type="continuous">
        <parent link="base_link"/>
        <child link="back_left_wheel"/>
        <origin xyz="-0.2 0.2 -0.1"/>
        <axis xyz="0 1 0"/>
    </joint>
    <link name="back_right_wheel">
        <visual>
            <geometry>
                <cylinder length="0.1" radius="0.1"/>
            </geometry>
            <origin xyz="0 0 0" rpy="1.571 0 0"/>
        </visual>
        <inertial>
            <mass value="2"/>
            <inertia ixx="0.6" ixy="0.0" ixz="0.0" iyy="0.2" iyz="0.0" izz="0.2"/>
            <origin xyz="0 0 0" rpy="1.571 0 0"/>
        </inertial>
        <collision>
            <geometry>
                <cylinder length="0.1" radius="0.1"/>
            </geometry>
            <origin xyz="0 0 0" rpy="1.571 0 0"/>
        </collision>
    </link>
    <joint name="base_to_back_right" type="continuous">
        <parent link="base_link"/>
        <child link="back_right_wheel"/>
        <origin xyz="-0.2 -0.2 -0.1"/>
        <axis xyz="0 1 0"/>
    </joint>
    <!--xacro:include filename="$(find realsense_gazebo_plugin)/urdf/realsense-RS200.macro.xacro" ns="front"/>
    <xacro:front.realsense-rs200
        prefix="front"
        parent="base_link">
        <origin
            xyz="0.2 0 0.075"
            rpy="0 0.3 0" />
        <cameraPrefix>front</cameraPrefix>
    </xacro:front.realsense-rs200>
    <xacro:include filename="$(find realsense_gazebo_plugin)/urdf/realsense-RS200.macro.xacro" ns="back"/>
    <xacro:back.realsense-rs200
        prefix="back"
        parent="base_link">
        <origin
            xyz="-0.2 0 0.075"
            rpy="0 0.5 3.14159" />
        <cameraPrefix>back</cameraPrefix>
    </xacro:back.realsense-rs200-->
    <transmission name="front_left_trans">
        <type>transmission_interface/SimpleTransmission</type>
        <joint name="base_to_front_left">
            <hardwareInterface>hardware_interface/VelocityJointInterface</hardwareInterface>
        </joint>
        <actuator name="front_left_motor">
            <hardwareInterface>hardware_interface/VelocityJointInterface</hardwareInterface>
            <mechanicalReduction>1</mechanicalReduction>
        </actuator>
    </transmission>
    <transmission name="back_left_trans">
        <type>transmission_interface/SimpleTransmission</type>
        <joint name="base_to_back_left">
            <hardwareInterface>hardware_interface/VelocityJointInterface</hardwareInterface>
        </joint>
        <actuator name="back_left_motor">
            <hardwareInterface>hardware_interface/VelocityJointInterface</hardwareInterface>
            <mechanicalReduction>1</mechanicalReduction>
        </actuator>
    </transmission>
    <transmission name="front_right_trans">
        <type>transmission_interface/SimpleTransmission</type>
        <joint name="base_to_front_right">
            <hardwareInterface>hardware_interface/VelocityJointInterface</hardwareInterface>
        </joint>
        <actuator name="front_right_motor">
            <hardwareInterface>hardware_interface/VelocityJointInterface</hardwareInterface>
            <mechanicalReduction>1</mechanicalReduction>
        </actuator>
    </transmission>
    <transmission name="back_right_trans">
        <type>transmission_interface/SimpleTransmission</type>
        <joint name="base_to_back_right">
            <hardwareInterface>hardware_interface/VelocityJointInterface</hardwareInterface>
        </joint>
        <actuator name="back_right_motor">
            <hardwareInterface>hardware_interface/VelocityJointInterface</hardwareInterface>
            <mechanicalReduction>1</mechanicalReduction>
        </actuator>
    </transmission>
</robot>
